[2024-04-07T03:20:10.481+0000] {taskinstance.py:1979} INFO - Dependencies all met for dep_context=non-requeueable deps ti=<TaskInstance: batch_etl.uploadingmovies_casts manual__2024-04-07T02:56:27.161905+00:00 [queued]>
[2024-04-07T03:20:10.484+0000] {taskinstance.py:1979} INFO - Dependencies all met for dep_context=requeueable deps ti=<TaskInstance: batch_etl.uploadingmovies_casts manual__2024-04-07T02:56:27.161905+00:00 [queued]>
[2024-04-07T03:20:10.484+0000] {taskinstance.py:2193} INFO - Starting attempt 2 of 2
[2024-04-07T03:20:10.491+0000] {taskinstance.py:2217} INFO - Executing <Task(PythonOperator): uploadingmovies_casts> on 2024-04-07 02:56:27.161905+00:00
[2024-04-07T03:20:10.494+0000] {standard_task_runner.py:60} INFO - Started process 135 to run task
[2024-04-07T03:20:10.496+0000] {standard_task_runner.py:87} INFO - Running: ['***', 'tasks', 'run', 'batch_etl', 'uploadingmovies_casts', 'manual__2024-04-07T02:56:27.161905+00:00', '--job-id', '37', '--raw', '--subdir', 'DAGS_FOLDER/batch_etl_dag.py', '--cfg-path', '/tmp/tmpiix5013x']
[2024-04-07T03:20:10.498+0000] {standard_task_runner.py:88} INFO - Job 37: Subtask uploadingmovies_casts
[2024-04-07T03:20:10.517+0000] {task_command.py:423} INFO - Running <TaskInstance: batch_etl.uploadingmovies_casts manual__2024-04-07T02:56:27.161905+00:00 [running]> on host befaceac7652
[2024-04-07T03:20:10.550+0000] {taskinstance.py:2513} INFO - Exporting env vars: AIRFLOW_CTX_DAG_OWNER='***' AIRFLOW_CTX_DAG_ID='batch_etl' AIRFLOW_CTX_TASK_ID='uploadingmovies_casts' AIRFLOW_CTX_EXECUTION_DATE='2024-04-07T02:56:27.161905+00:00' AIRFLOW_CTX_TRY_NUMBER='2' AIRFLOW_CTX_DAG_RUN_ID='manual__2024-04-07T02:56:27.161905+00:00'
[2024-04-07T03:20:11.427+0000] {taskinstance.py:2731} ERROR - Task failed with exception
Traceback (most recent call last):
  File "/home/airflow/.local/lib/python3.8/site-packages/airflow/models/taskinstance.py", line 444, in _execute_task
    result = _execute_callable(context=context, **execute_callable_kwargs)
  File "/home/airflow/.local/lib/python3.8/site-packages/airflow/models/taskinstance.py", line 414, in _execute_callable
    return execute_callable(context=context, **execute_callable_kwargs)
  File "/home/airflow/.local/lib/python3.8/site-packages/airflow/operators/python.py", line 200, in execute
    return_value = self.execute_callable()
  File "/home/airflow/.local/lib/python3.8/site-packages/airflow/operators/python.py", line 217, in execute_callable
    return self.python_callable(*self.op_args, **self.op_kwargs)
  File "/opt/airflow/dags/database/lake.py", line 46, in upload_blob
    bucket = client.get_bucket(bucket_name)
  File "/home/airflow/.local/lib/python3.8/site-packages/google/cloud/storage/client.py", line 857, in get_bucket
    bucket.reload(
  File "/home/airflow/.local/lib/python3.8/site-packages/google/cloud/storage/bucket.py", line 1083, in reload
    super(Bucket, self).reload(
  File "/home/airflow/.local/lib/python3.8/site-packages/google/cloud/storage/_helpers.py", line 300, in reload
    api_response = client._get_resource(
  File "/home/airflow/.local/lib/python3.8/site-packages/google/cloud/storage/client.py", line 462, in _get_resource
    return self._connection.api_request(
  File "/home/airflow/.local/lib/python3.8/site-packages/google/cloud/storage/_http.py", line 78, in api_request
    return call()
  File "/home/airflow/.local/lib/python3.8/site-packages/google/api_core/retry/retry_unary.py", line 293, in retry_wrapped_func
    return retry_target(
  File "/home/airflow/.local/lib/python3.8/site-packages/google/api_core/retry/retry_unary.py", line 153, in retry_target
    _retry_error_helper(
  File "/home/airflow/.local/lib/python3.8/site-packages/google/api_core/retry/retry_base.py", line 212, in _retry_error_helper
    raise final_exc from source_exc
  File "/home/airflow/.local/lib/python3.8/site-packages/google/api_core/retry/retry_unary.py", line 144, in retry_target
    result = target()
  File "/home/airflow/.local/lib/python3.8/site-packages/google/cloud/_http/__init__.py", line 494, in api_request
    raise exceptions.from_http_response(response)
google.api_core.exceptions.NotFound: 404 GET https://storage.googleapis.com/storage/v1/b/is3107_datalake?projection=noAcl&prettyPrint=false: The specified bucket does not exist.
[2024-04-07T03:20:11.449+0000] {taskinstance.py:1149} INFO - Marking task as FAILED. dag_id=batch_etl, task_id=uploadingmovies_casts, execution_date=20240407T025627, start_date=20240407T032010, end_date=20240407T032011
[2024-04-07T03:20:11.465+0000] {standard_task_runner.py:107} ERROR - Failed to execute job 37 for task uploadingmovies_casts (404 GET https://storage.googleapis.com/storage/v1/b/is3107_datalake?projection=noAcl&prettyPrint=false: The specified bucket does not exist.; 135)
[2024-04-07T03:20:11.513+0000] {local_task_job_runner.py:234} INFO - Task exited with return code 1
[2024-04-07T03:20:11.537+0000] {taskinstance.py:3312} INFO - 0 downstream tasks scheduled from follow-on schedule check
