[2024-04-07T03:15:45.998+0000] {taskinstance.py:1979} INFO - Dependencies all met for dep_context=non-requeueable deps ti=<TaskInstance: batch_etl.uploadingmovies_casts manual__2024-04-07T02:56:27.161905+00:00 [queued]>
[2024-04-07T03:15:46.016+0000] {taskinstance.py:1979} INFO - Dependencies all met for dep_context=requeueable deps ti=<TaskInstance: batch_etl.uploadingmovies_casts manual__2024-04-07T02:56:27.161905+00:00 [queued]>
[2024-04-07T03:15:46.017+0000] {taskinstance.py:2193} INFO - Starting attempt 1 of 1
[2024-04-07T03:15:46.033+0000] {taskinstance.py:2217} INFO - Executing <Task(PythonOperator): uploadingmovies_casts> on 2024-04-07 02:56:27.161905+00:00
[2024-04-07T03:15:46.043+0000] {standard_task_runner.py:60} INFO - Started process 1238 to run task
[2024-04-07T03:15:46.052+0000] {standard_task_runner.py:87} INFO - Running: ['***', 'tasks', 'run', 'batch_etl', 'uploadingmovies_casts', 'manual__2024-04-07T02:56:27.161905+00:00', '--job-id', '32', '--raw', '--subdir', 'DAGS_FOLDER/batch_etl_dag.py', '--cfg-path', '/tmp/tmp0xnm69ka']
[2024-04-07T03:15:46.058+0000] {standard_task_runner.py:88} INFO - Job 32: Subtask uploadingmovies_casts
[2024-04-07T03:15:46.118+0000] {task_command.py:423} INFO - Running <TaskInstance: batch_etl.uploadingmovies_casts manual__2024-04-07T02:56:27.161905+00:00 [running]> on host 0e5532b210db
[2024-04-07T03:15:46.203+0000] {taskinstance.py:2513} INFO - Exporting env vars: AIRFLOW_CTX_DAG_OWNER='***' AIRFLOW_CTX_DAG_ID='batch_etl' AIRFLOW_CTX_TASK_ID='uploadingmovies_casts' AIRFLOW_CTX_EXECUTION_DATE='2024-04-07T02:56:27.161905+00:00' AIRFLOW_CTX_TRY_NUMBER='1' AIRFLOW_CTX_DAG_RUN_ID='manual__2024-04-07T02:56:27.161905+00:00'
[2024-04-07T03:15:46.205+0000] {taskinstance.py:2731} ERROR - Task failed with exception
Traceback (most recent call last):
  File "/home/airflow/.local/lib/python3.8/site-packages/airflow/models/taskinstance.py", line 444, in _execute_task
    result = _execute_callable(context=context, **execute_callable_kwargs)
  File "/home/airflow/.local/lib/python3.8/site-packages/airflow/models/taskinstance.py", line 414, in _execute_callable
    return execute_callable(context=context, **execute_callable_kwargs)
  File "/home/airflow/.local/lib/python3.8/site-packages/airflow/operators/python.py", line 200, in execute
    return_value = self.execute_callable()
  File "/home/airflow/.local/lib/python3.8/site-packages/airflow/operators/python.py", line 217, in execute_callable
    return self.python_callable(*self.op_args, **self.op_kwargs)
  File "/opt/airflow/dags/database/lake.py", line 43, in upload_blob
    client = storage.Client.from_service_account_json(
  File "/home/airflow/.local/lib/python3.8/site-packages/google/cloud/client/__init__.py", line 106, in from_service_account_json
    with io.open(json_credentials_path, "r", encoding="utf-8") as json_fi:
FileNotFoundError: [Errno 2] No such file or directory: '.google/credentials.json'
[2024-04-07T03:15:46.218+0000] {taskinstance.py:1149} INFO - Marking task as FAILED. dag_id=batch_etl, task_id=uploadingmovies_casts, execution_date=20240407T025627, start_date=20240407T031546, end_date=20240407T031546
[2024-04-07T03:15:46.227+0000] {standard_task_runner.py:107} ERROR - Failed to execute job 32 for task uploadingmovies_casts ([Errno 2] No such file or directory: '.google/credentials.json'; 1238)
[2024-04-07T03:15:46.275+0000] {local_task_job_runner.py:234} INFO - Task exited with return code 1
[2024-04-07T03:15:46.296+0000] {taskinstance.py:3312} INFO - 0 downstream tasks scheduled from follow-on schedule check
