[2024-04-07T03:20:39.711+0000] {taskinstance.py:1979} INFO - Dependencies all met for dep_context=non-requeueable deps ti=<TaskInstance: sql_migration_dag.set_up_datawarehouse manual__2024-04-07T03:20:36.869041+00:00 [queued]>
[2024-04-07T03:20:39.725+0000] {taskinstance.py:1979} INFO - Dependencies all met for dep_context=requeueable deps ti=<TaskInstance: sql_migration_dag.set_up_datawarehouse manual__2024-04-07T03:20:36.869041+00:00 [queued]>
[2024-04-07T03:20:39.729+0000] {taskinstance.py:2193} INFO - Starting attempt 1 of 1
[2024-04-07T03:20:39.747+0000] {taskinstance.py:2217} INFO - Executing <Task(_PythonDecoratedOperator): set_up_datawarehouse> on 2024-04-07 03:20:36.869041+00:00
[2024-04-07T03:20:39.756+0000] {standard_task_runner.py:60} INFO - Started process 149 to run task
[2024-04-07T03:20:39.760+0000] {standard_task_runner.py:87} INFO - Running: ['***', 'tasks', 'run', 'sql_migration_dag', 'set_up_datawarehouse', 'manual__2024-04-07T03:20:36.869041+00:00', '--job-id', '39', '--raw', '--subdir', 'DAGS_FOLDER/db_migration_dag.py', '--cfg-path', '/tmp/tmp3x1pzzem']
[2024-04-07T03:20:39.771+0000] {standard_task_runner.py:88} INFO - Job 39: Subtask set_up_datawarehouse
[2024-04-07T03:20:39.829+0000] {task_command.py:423} INFO - Running <TaskInstance: sql_migration_dag.set_up_datawarehouse manual__2024-04-07T03:20:36.869041+00:00 [running]> on host befaceac7652
[2024-04-07T03:20:39.875+0000] {taskinstance.py:2513} INFO - Exporting env vars: AIRFLOW_CTX_DAG_OWNER='***' AIRFLOW_CTX_DAG_ID='sql_migration_dag' AIRFLOW_CTX_TASK_ID='set_up_datawarehouse' AIRFLOW_CTX_EXECUTION_DATE='2024-04-07T03:20:36.869041+00:00' AIRFLOW_CTX_TRY_NUMBER='1' AIRFLOW_CTX_DAG_RUN_ID='manual__2024-04-07T03:20:36.869041+00:00'
[2024-04-07T03:20:39.883+0000] {taskinstance.py:2731} ERROR - Task failed with exception
Traceback (most recent call last):
  File "/home/airflow/.local/lib/python3.8/site-packages/mysql/connector/connection_cext.py", line 323, in _open_connection
    self._cmysql.connect(**cnx_kwargs)
_mysql_connector.MySQLInterfaceError: Can't connect to MySQL server on 'host.docker.internal:3306' (111)

The above exception was the direct cause of the following exception:

Traceback (most recent call last):
  File "/home/airflow/.local/lib/python3.8/site-packages/airflow/models/taskinstance.py", line 444, in _execute_task
    result = _execute_callable(context=context, **execute_callable_kwargs)
  File "/home/airflow/.local/lib/python3.8/site-packages/airflow/models/taskinstance.py", line 414, in _execute_callable
    return execute_callable(context=context, **execute_callable_kwargs)
  File "/home/airflow/.local/lib/python3.8/site-packages/airflow/decorators/base.py", line 241, in execute
    return_value = super().execute(context)
  File "/home/airflow/.local/lib/python3.8/site-packages/airflow/operators/python.py", line 200, in execute
    return_value = self.execute_callable()
  File "/home/airflow/.local/lib/python3.8/site-packages/airflow/operators/python.py", line 217, in execute_callable
    return self.python_callable(*self.op_args, **self.op_kwargs)
  File "/opt/airflow/dags/db_migration_dag.py", line 30, in set_up_databases
    create_drop_new_database(database, "CREATE")
  File "/opt/airflow/dags/database/warehouse.py", line 21, in create_drop_new_database
    conn = mysql.connector.connect(
  File "/home/airflow/.local/lib/python3.8/site-packages/mysql/connector/pooling.py", line 322, in connect
    return CMySQLConnection(*args, **kwargs)
  File "/home/airflow/.local/lib/python3.8/site-packages/mysql/connector/connection_cext.py", line 140, in __init__
    self.connect(**kwargs)
  File "/home/airflow/.local/lib/python3.8/site-packages/mysql/connector/abstracts.py", line 1363, in connect
    self._open_connection()
  File "/home/airflow/.local/lib/python3.8/site-packages/mysql/connector/connection_cext.py", line 328, in _open_connection
    raise get_mysql_exception(
mysql.connector.errors.DatabaseError: 2003 (HY000): Can't connect to MySQL server on 'host.docker.internal:3306' (111)
[2024-04-07T03:20:39.892+0000] {taskinstance.py:1149} INFO - Marking task as FAILED. dag_id=sql_migration_dag, task_id=set_up_datawarehouse, execution_date=20240407T032036, start_date=20240407T032039, end_date=20240407T032039
[2024-04-07T03:20:39.901+0000] {standard_task_runner.py:107} ERROR - Failed to execute job 39 for task set_up_datawarehouse (2003 (HY000): Can't connect to MySQL server on 'host.docker.internal:3306' (111); 149)
[2024-04-07T03:20:39.944+0000] {local_task_job_runner.py:234} INFO - Task exited with return code 1
[2024-04-07T03:20:39.957+0000] {taskinstance.py:3312} INFO - 0 downstream tasks scheduled from follow-on schedule check
