[2024-04-07T07:44:47.866+0000] {taskinstance.py:1979} INFO - Dependencies all met for dep_context=non-requeueable deps ti=<TaskInstance: setup.set_up_datawarehouse manual__2024-04-07T07:44:45.349792+00:00 [queued]>
[2024-04-07T07:44:47.870+0000] {taskinstance.py:1979} INFO - Dependencies all met for dep_context=requeueable deps ti=<TaskInstance: setup.set_up_datawarehouse manual__2024-04-07T07:44:45.349792+00:00 [queued]>
[2024-04-07T07:44:47.870+0000] {taskinstance.py:2193} INFO - Starting attempt 1 of 1
[2024-04-07T07:44:47.875+0000] {taskinstance.py:2217} INFO - Executing <Task(_PythonDecoratedOperator): set_up_datawarehouse> on 2024-04-07 07:44:45.349792+00:00
[2024-04-07T07:44:47.879+0000] {standard_task_runner.py:60} INFO - Started process 67 to run task
[2024-04-07T07:44:47.881+0000] {standard_task_runner.py:87} INFO - Running: ['***', 'tasks', 'run', 'setup', 'set_up_datawarehouse', 'manual__2024-04-07T07:44:45.349792+00:00', '--job-id', '6', '--raw', '--subdir', 'DAGS_FOLDER/setup.py', '--cfg-path', '/tmp/tmprdw6_z5l']
[2024-04-07T07:44:47.882+0000] {standard_task_runner.py:88} INFO - Job 6: Subtask set_up_datawarehouse
[2024-04-07T07:44:47.902+0000] {task_command.py:423} INFO - Running <TaskInstance: setup.set_up_datawarehouse manual__2024-04-07T07:44:45.349792+00:00 [running]> on host ea99b2a4c9f6
[2024-04-07T07:44:47.933+0000] {taskinstance.py:2513} INFO - Exporting env vars: AIRFLOW_CTX_DAG_OWNER='***' AIRFLOW_CTX_DAG_ID='setup' AIRFLOW_CTX_TASK_ID='set_up_datawarehouse' AIRFLOW_CTX_EXECUTION_DATE='2024-04-07T07:44:45.349792+00:00' AIRFLOW_CTX_TRY_NUMBER='1' AIRFLOW_CTX_DAG_RUN_ID='manual__2024-04-07T07:44:45.349792+00:00'
[2024-04-07T07:44:47.977+0000] {warehouse.py:54} ERROR - Database already exists!!
[2024-04-07T07:44:47.977+0000] {warehouse.py:75} INFO - {'host': 'host.docker.internal', 'user': 'root', 'password': '***', 'database': 'dashboard', 'allow_local_infile': True}
[2024-04-07T07:44:48.014+0000] {warehouse.py:95} INFO - SUCCESSFULLY EXECUTED QUERIES
[2024-04-07T07:44:48.061+0000] {warehouse.py:54} ERROR - Database already exists!!
[2024-04-07T07:44:48.062+0000] {warehouse.py:75} INFO - {'host': 'host.docker.internal', 'user': 'root', 'password': '***', 'database': 'machinelearning', 'allow_local_infile': True}
[2024-04-07T07:44:48.096+0000] {warehouse.py:95} INFO - SUCCESSFULLY EXECUTED QUERIES
[2024-04-07T07:44:48.129+0000] {warehouse.py:54} ERROR - Database already exists!!
[2024-04-07T07:44:48.130+0000] {warehouse.py:75} INFO - {'host': 'host.docker.internal', 'user': 'root', 'password': '***', 'database': 'datawarehouse', 'allow_local_infile': True}
[2024-04-07T07:44:48.166+0000] {warehouse.py:95} INFO - SUCCESSFULLY EXECUTED QUERIES
[2024-04-07T07:44:48.167+0000] {python.py:202} INFO - Done. Returned value was: None
[2024-04-07T07:44:48.172+0000] {taskinstance.py:1149} INFO - Marking task as SUCCESS. dag_id=setup, task_id=set_up_datawarehouse, execution_date=20240407T074445, start_date=20240407T074447, end_date=20240407T074448
[2024-04-07T07:44:48.182+0000] {local_task_job_runner.py:234} INFO - Task exited with return code 0
[2024-04-07T07:44:48.195+0000] {taskinstance.py:3312} INFO - 1 downstream tasks scheduled from follow-on schedule check
