[2024-04-07T03:55:00.997+0000] {taskinstance.py:1979} INFO - Dependencies all met for dep_context=non-requeueable deps ti=<TaskInstance: setup.set_up_datalake manual__2024-04-07T03:54:58.082620+00:00 [queued]>
[2024-04-07T03:55:01.001+0000] {taskinstance.py:1979} INFO - Dependencies all met for dep_context=requeueable deps ti=<TaskInstance: setup.set_up_datalake manual__2024-04-07T03:54:58.082620+00:00 [queued]>
[2024-04-07T03:55:01.001+0000] {taskinstance.py:2193} INFO - Starting attempt 1 of 1
[2024-04-07T03:55:01.008+0000] {taskinstance.py:2217} INFO - Executing <Task(_PythonDecoratedOperator): set_up_datalake> on 2024-04-07 03:54:58.082620+00:00
[2024-04-07T03:55:01.011+0000] {standard_task_runner.py:60} INFO - Started process 1218 to run task
[2024-04-07T03:55:01.013+0000] {standard_task_runner.py:87} INFO - Running: ['***', 'tasks', 'run', 'setup', 'set_up_datalake', 'manual__2024-04-07T03:54:58.082620+00:00', '--job-id', '75', '--raw', '--subdir', 'DAGS_FOLDER/setup.py', '--cfg-path', '/tmp/tmpuiao1xcf']
[2024-04-07T03:55:01.015+0000] {standard_task_runner.py:88} INFO - Job 75: Subtask set_up_datalake
[2024-04-07T03:55:01.039+0000] {task_command.py:423} INFO - Running <TaskInstance: setup.set_up_datalake manual__2024-04-07T03:54:58.082620+00:00 [running]> on host befaceac7652
[2024-04-07T03:55:01.073+0000] {taskinstance.py:2513} INFO - Exporting env vars: AIRFLOW_CTX_DAG_OWNER='***' AIRFLOW_CTX_DAG_ID='setup' AIRFLOW_CTX_TASK_ID='set_up_datalake' AIRFLOW_CTX_EXECUTION_DATE='2024-04-07T03:54:58.082620+00:00' AIRFLOW_CTX_TRY_NUMBER='1' AIRFLOW_CTX_DAG_RUN_ID='manual__2024-04-07T03:54:58.082620+00:00'
[2024-04-07T03:55:01.857+0000] {taskinstance.py:2731} ERROR - Task failed with exception
Traceback (most recent call last):
  File "/home/airflow/.local/lib/python3.8/site-packages/airflow/models/taskinstance.py", line 444, in _execute_task
    result = _execute_callable(context=context, **execute_callable_kwargs)
  File "/home/airflow/.local/lib/python3.8/site-packages/airflow/models/taskinstance.py", line 414, in _execute_callable
    return execute_callable(context=context, **execute_callable_kwargs)
  File "/home/airflow/.local/lib/python3.8/site-packages/airflow/decorators/base.py", line 241, in execute
    return_value = super().execute(context)
  File "/home/airflow/.local/lib/python3.8/site-packages/airflow/operators/python.py", line 200, in execute
    return_value = self.execute_callable()
  File "/home/airflow/.local/lib/python3.8/site-packages/airflow/operators/python.py", line 217, in execute_callable
    return self.python_callable(*self.op_args, **self.op_kwargs)
  File "/opt/airflow/dags/setup.py", line 41, in set_up_datalake
    create_bucket(BUCKETNAME)
  File "/opt/airflow/dags/database/lake.py", line 30, in create_bucket
    bucket = client.create_bucket(bucket_name)
  File "/home/airflow/.local/lib/python3.8/site-packages/google/cloud/storage/client.py", line 1044, in create_bucket
    api_response = self._post_resource(
  File "/home/airflow/.local/lib/python3.8/site-packages/google/cloud/storage/client.py", line 702, in _post_resource
    return self._connection.api_request(
  File "/home/airflow/.local/lib/python3.8/site-packages/google/cloud/storage/_http.py", line 78, in api_request
    return call()
  File "/home/airflow/.local/lib/python3.8/site-packages/google/api_core/retry/retry_unary.py", line 293, in retry_wrapped_func
    return retry_target(
  File "/home/airflow/.local/lib/python3.8/site-packages/google/api_core/retry/retry_unary.py", line 153, in retry_target
    _retry_error_helper(
  File "/home/airflow/.local/lib/python3.8/site-packages/google/api_core/retry/retry_base.py", line 212, in _retry_error_helper
    raise final_exc from source_exc
  File "/home/airflow/.local/lib/python3.8/site-packages/google/api_core/retry/retry_unary.py", line 144, in retry_target
    result = target()
  File "/home/airflow/.local/lib/python3.8/site-packages/google/cloud/_http/__init__.py", line 494, in api_request
    raise exceptions.from_http_response(response)
google.api_core.exceptions.Conflict: 409 POST https://storage.googleapis.com/storage/v1/b?project=is3107-g1&prettyPrint=false: Your previous request to create the named bucket succeeded and you already own it.
[2024-04-07T03:55:01.864+0000] {taskinstance.py:1149} INFO - Marking task as FAILED. dag_id=setup, task_id=set_up_datalake, execution_date=20240407T035458, start_date=20240407T035500, end_date=20240407T035501
[2024-04-07T03:55:01.871+0000] {standard_task_runner.py:107} ERROR - Failed to execute job 75 for task set_up_datalake (409 POST https://storage.googleapis.com/storage/v1/b?project=is3107-g1&prettyPrint=false: Your previous request to create the named bucket succeeded and you already own it.; 1218)
[2024-04-07T03:55:01.901+0000] {local_task_job_runner.py:234} INFO - Task exited with return code 1
[2024-04-07T03:55:01.913+0000] {taskinstance.py:3312} INFO - 0 downstream tasks scheduled from follow-on schedule check
